# 47장 에러처리

##  47.1 에러 처리의 필요성

에러는 언제나 발생할 수 있고, 발생한 에러에 대해 대처하지 않고 방치하면 프로그램은 강제종료 된다.

직접적으로 에러를 발생하지 않는 예외적인 상황이 발생할 수도 있다. 예외적인 상황에 적절하게 대응하지 않으면 에러로 이어질 가능성이 크다.

```js
const $elem = document.querySelector('#1');
// DOMException: Failed to execute 'querySelector' on 'Document': '#1' is not a valid selector.
```

```js
// DOM에 button 요소가 존재하는 경우 querySelector 메서드는 에러를 발생시키지 않고 null을 반환한다.
const $button = document.querySelector('button'); // null
$button?.classList.add('disabled');
```

querySelector메서드는 인수로 전달한 문자열이 CSS 선택자 문법에 맞지 않는 경우 에러를 발생시킨다. 하지만, 인수로 전달한 CSS 선택자 문자열로 DOM에서 요소 노드를 찾을 수 없는 경우 에러를 발생시키지 않고, null을 반환한다.

이때 if문으로 querySelector 메서드의 반환값을 확인하거나 단축 평가 또는 옵셔널체이닝연산자(?.)를 사용하지 않으면 에러로 이어질 가능성이 크다.

예외 상황이 너무나 다양하기 때문에 아무런 조치도 하지 않아 강제종료된다면 원인을 찾기도 어렵다. 그렇기 때문에 **언제나 에러나 예외적인 상황이 발생할 수 있다는 것을 전제하고 이에 대응하는 코드를 작성하는 것이 중요**하다.

<br/><br/>

## 47.2 try...catch...finally문

기본적으로 에러 처리를 구현하는 방법은 크게 2가지가 있다.

* 예외적인 상황이 발생하면 반환하는 값을 if문이나 `단축 평가` 또는 `옵셔널 체이닝 연산자`를 통해 확인해서 처리하는 방법
* 에러 처리 코드를 미리 등록해 두고 에러가 발생하면 에러 처리코드로 점프하도록 하는 방법

`try...catch...finally`는 2번째 방법에 해당하며 이를 일반적으로 `에러 처리`라고 한다.

```js
console.log('[Start]');

try {
  // 실행할 코드(에러가 발생할 가능성이 있는 코드)
  foo();
} catch (err) {
  // try 코드 블록에서 에러가 발생하면 이 코드 블록의 코드가 실행된다.
  // err에는 try 코드 블록에서 발생한 Error 객체가 전달된다.
  console.error(err); // ReferenceError: foo is not defined
} finally {
  // 에러 발생과 상관없이 반드시 한 번 실행된다.
  console.log('finally');
}

// try...catch...finally 문으로 에러를 처리하면 프로그램이 강제 종료되지 않는다.
console.log('[End]');
```

<br/><br/>

## 47.3 Error 객체

Error생성자 함수는 에러 객체를 생성한다. Error생성자 함수에는 에러를 상세히 설명하는 에러 메세지를 인수로 전달할 수 있다

```js
const error = new Error('invalid');
```

<br/>

Error생성자 함수가 생성한 에러 객체는 `message프로퍼티`와 `stack 프로퍼티`를 갖는다. `message프로퍼티`의 값은 Error생성자 함수에 인수로 전달한 **에러 메세지**이고, `stack프로퍼티` 값은 에러를 발생시킨 콜 스택의 **호출 정보**를 나타내는 문자열이며 디버깅 목적으로 사용한다.

자바스크립트는 7가지 에러 객체를 생성할 수 있는 Error 생성자 함수를 제공한다.

* Error
* SyntaxError
* ReferenceError
* TypeError
* RangeError
* URIError
* EvalError

```js
1 @ 1;    // SyntaxError: Invalid or unexpected token
foo();    // ReferenceError: foo is not defined
null.foo; // TypeError: Cannot read property 'foo' of null
new Array(-1); // RangeError: Invalid array length
decodeURIComponent('%'); // URIError: URI malformed
```

<br/><br/>

## 47.4 throw문

Error생성자 함수로 에러 객체를 생성한다고 에러가 발생하는 것은 아니다.

**❗ 에러 객체 생성과 에러 발생은 의미가 다르다.**

에러를 발생 시키려면 `throw문`으로 에러 객체를 던져야 한다.

```js
throw 표현식;
```

`throw문`의 표현식은 어떤 값이라도 상관없지만 일반적으로 에러 객체를 지정한다. 에러를 던지면 catch문의 에러변수가 생성되고 던져진 에러 객체가 할당된다. 그리고 catch코드 블록이 실행되기 시작한다.

```js
try {
  // 에러 객체를 던지면 catch 코드 블록이 실행되기 시작한다.
  throw new Error('something wrong');
} catch (error) {
  console.log(error);
}
```

```js
// 외부에서 전달받은 콜백 함수를 n번만큼 반복 호출한다
const repeat = (n, f) => {
  // 매개변수 f에 전달된 인수가 함수가 아니면 TypeError를 발생시킨다.
  if (typeof f !== 'function') throw new TypeError('f must be a function');

  for (var i = 0; i < n; i++) {
    f(i); // i를 전달하면서 f를 호출
  }
};

try {
  repeat(2, 1); // 두 번째 인수가 함수가 아니므로 TypeError가 발생(throw)한다.
} catch (err) {
  console.error(err); // TypeError: f must be a function
}
```

<br/><br/>

## 47.5 에러의 전파

> 다시 한번!
>
> 에러는 호출자 방향으로 전파된다.

```js
const foo = () => {
  throw Error('foo에서 발생한 에러'); // ④
};

const bar = () => {
  foo(); // ③
};

const baz = () => {
  bar(); // ②
};

try {
  baz(); // ①
} catch (err) {
  console.error(err);
}
```

1에서 baz함수를 호출하면, 2에서 bar함수가 호출되고, 3에서 foo함수가 호출되고 foo함수는 4에서 에러를 throw한다. 이때 foo함수가 throw한 에러는 다음과 같이 호출자에게 전파되어 전역에서 캐치된다.

이처런 throw된 에러를 캐치하지 않으면 호출자 방향으로 전파된다. 이때 throw된 에러를 캐치하여 적절히 대응하여 실행 흐름을 복구할 수 있다.

주의할 것은 비동기 함수인 setTimeout이나 프로미스 후속 처리 메서드의 콜백 함수는 호출자가 없다는 것이다. setTimeout이나 프로미스 후속 처리 메서드의 콜백 함수는 태스크 큐나 마이크로태스크 큐에 일시 저장되었다가 콜 스택이 비면 이벤트 루프에 의해 콜 스택으로 푸시되어 실행된다. 이때 콜 스택에 푸시된 콜백함수의 실행 컨텍스트는 콜 스택의 가장 하부에 존재하게 된다.

따라서 에러를 전파할 호출자가 존재하지 않는다.